Workbook

Sheet Comparision
A2: Sinario | B2: Initial cash required | C2: Project Profit | D2: JV Share | E2: Developer
A3: Rental Approach @ 70% LVR | B3: ='7 Yr Valuation & Cashflow'!L8 -> 1199892 | C3: ='7 Yr Valuation & Cashflow'!D22 -> 539448 | D3: ='7 Yr Valuation & Cashflow'!M15 -> 0.60352941 | E3: =+(100%-D3)*C3 -> 213875.27 | F3: 1 Yr
A4: Sell both @ 70% LVR | B4: ='2 x Land Sales@ 70LVR'!F27 -> 1164104 | C4: ='2 x Land Sales@ 70LVR'!B90 -> 359375.8 | D4: ='2 x Land Sales@ 70LVR'!D59 -> 0.50676471 | E4: =+(100%-D4)*C4 -> 177256.83
A5: Sell both @ 80% LVR | B5: ='2 x Land Sales@ 80 LVR'!F28 -> 942047.6 | C5: ='2 x Land Sales@ 80 LVR'!B75 -> 271875 | D5: ='2 x Land Sales@ 80 LVR'!E50 -> 0.42352941 | E5: =+(100%-D5)*C5 -> 156727.94
A6: Sell 1 and hold 1 @ 70% LVR | B6: ='Sell 1 hold 1 at 70% LVR'!F27 -> 1170852 | C6: ='Sell 1 hold 1 at 70% LVR'!D59 -> 397764.08 | D6: 0.6 | E6: =+(100%-D6)*C6 -> 159105.63 | F6: 1 Yr
A13: Quotes
A15: Demo (incl GST) | B15: A1 | C15: Nu Tec | D15: AMW
A17: Demo 94-96 | B17: 76400 | C17: =30000*1.1 -> 33000
A18: Demo 92 | D18: 36300
A19: Asbestos Certificate | C19: =350*1.1 -> 385 | D19: 0
A20: Abolishment of Electricity 94-96 | B20: =550*10 -> 5500 | C20: =550*10 -> 5500 | D20: =550*10 -> 5500
A21: Abolishment of Gas | B21: =770*10 -> 7700 | C21: =252*10 -> 2520 | D21: =252*10 -> 2520
A22: Temp Fencing | B22: 880 | D22: 600
A23: Sewer Caping | B23: 1540 | C23: =1200*1.1 -> 1320
A24: Stumping | C24: =250*1.1 -> 275
A25: Admin Fee | C25: =250*1.1 -> 275
A28: Total | B28: =SUM(B17:B27) -> 92020 | C28: =SUM(C17:C27) -> 43275
A29: Deposit | C29: 0.2 | D29: 0.3
A30: Asbestos Included | B30: Yes | C30: Yes | D30: No
A32: Temp Fence Dimension | B32: Front | C32: Side
A33: 92 | B33: 15.3
A34: 94 | B34: 14.8
A35: 96 | B35: 15.3
B36: =SUM(B33:B35) -> 45.4

Sheet Capital Stack
A1: Yr # | B1: 1 | I1: Amt | J1: % | K1: Share per 100% | L1: val
B2: 2026 | H2: Stage 1 Capital Raising | I2: 800000 | J2: 0.42 | K2: =(100000/I2)*J2 -> 0.0525 | L2: =(100%/J2)*I2 -> 1904761.9
A3: Property Valuation | B3: ='7 Yr Valuation & Cashflow'!C5 -> 2760000 | H3: Stage 2 Capital Raising | I3: 450000 | J3: 0.18 | K3: =(100000/I3)*J3 -> 0.04 | L3: =(100%/J3)*I3 -> 2500000
A4: StampDuty | B4: ='7 Yr Valuation & Cashflow'!C7 -> 165600 | I4: =SUM(I2:I3) -> 1250000 | J4: =SUM(J2:J3) -> 0.6
A5: Closing costs + Due Dilligence | B5: ='7 Yr Valuation & Cashflow'!C8 -> 15000
A6: Finders fee | B6: ='7 Yr Valuation & Cashflow'!C9 -> 40000 | H6: Stage 2 Formaula
A7: Finance cost | B7: ='Senior Funding Model'!D20 -> 22252 | H7: Capital contribution | I7: =200000 -> 200000
A8: Operating Reserve & Repairs | B8: ='Sell 1 hold 1 at 70% LVR'!C26 -> 129040 | H8: % share
A9: Total Cost | B9: =SUM(B3:B8) -> 3131892
A11: Market Valuation (MV) | B11: 2760000 | H11: Graph
A12: LVR | B12: 0.7 | H12: Capital Stack | I12: Amount | J12: Stack | R12: 2950000
A13: Senior Loan | B13: =+B11*B12 -> 1932000 | H13: Senior Loan (70% LVR) | I13: =B13 -> 1932000 | J13: =+I13 -> 1932000 | R13: -100000 | S13: Deposit
A14: Cash required to settle | B14: =$B$9-(B11*B12) -> 1199892 | H14: Round 1 Capital Raising | I14: =800000 -> 800000 | J14: =+J13+I14 -> 2732000 | R14: -1932000
H15: Round 2 Capital Raising | I15: 200000 | J15: =+J14+I15 -> 2932000 | R15: =SUM(R12:R14) -> 918000
A16: Investors | B16: Amt Contributed | C16: % Interest in the deal | H16: Total Capital Stack
A17: Vish Associates Pty Ltd (ABN 56 647 166 112) ATF Narayan Family Wealth Trust | B17: 600000 | C17: =((400000/850000)*0.45)+(200000/450000)*0.18 -> 0.29176471
A18: Sharath Reddy Kancharla | B18: 195000 | C18: =(B18/850000)*0.45 -> 0.10323529
A19: ARVR Holdings PtyLtd ATF ARVR Family Trust | B19: 200000 | C19: =(B19/850000)*0.45 -> 0.10588235
A20: Krishna's Bucket Company | C20: =100%-C17-C18-C19 -> 0.49911765 | F20: Investor Payments
A21: Total | B21: =SUM(B17:B20) -> 995000 | C21: =SUM(C17:C20) -> 1 | F21: Date | G21: Vivek | H21: Sharath | I21: Vijay | J21: Ramakanth (loan)
F22: 45721 | H22: 10000
A23: Money Parter (Loan) | F23: 45729 | H23: 60000
A24: Ramakanth | B24: 150000 | F24: 45776 | G24: 35000
A25: Total Cash Raised | B25: =B21+B24 -> 1145000 | F25: 45777 | G25: 35000
F26: 45982 | G26: 25000
A27: Cash require | F27: 46003 | G27: 95000
A28: Homesly expenses | B28: 15000 | F28: 46006 | G28: 95000
A29: Equity 30% | B29: =B3*30% -> 828000 | F29: 46007 | G29: 55000
A30: Stamp Duty | B30: =B4 -> 165600 | F30: 46008 | G30: 50000
A31: Finders Fee | B31: =B6 -> 40000 | F31: 46016 | H31: 40000
A32: Finance Cost | B32: =B7 -> 22252 | F32: 46018 | H32: 40000 | I32: 3000
A33: Closing costs | B33: =B5 -> 15000 | F33: 46019 | H33: 50000
B34: =SUM(B28:B33) -> 1085852 | F34: 46020 | I34: =47000+50000+50000 -> 147000 | J34: 100000
A35: Deficit / Surplus | B35: =B25-B34 -> 59148 | F35: 46021 | I35: 50000 | J35: 50000
F36: 45662 | G36: 97000
F37: 45663 | G37: 100000
F38: 45695
F39: Paid to date | G39: =SUM(G22:G37) -> 587000 | H39: =SUM(H22:H37) -> 200000 | I39: =SUM(I22:I37) -> 200000 | J39: =SUM(J22:J37) -> 150000 | K39: =SUM(G39:J39) -> 1137000
F40: Committed | G40: 600000 | H40: 200000 | I40: 200000 | J40: 150000 | K40: =SUM(G40:J40) -> 1150000
F41: Outstanding | G41: =G40-G39 -> 13000 | H41: =H40-H39 -> 0 | I41: =I40-I39 -> 0 | J41: =J40-J39 -> 0 | K41: =SUM(G41:J41) -> 13000
...

Sheet cashflow
A1: PROJECT PROGRAMME | B1: Jan | C1: Feb | D1: Mar | E1: Apr | F1: May | G1: Jun | H1: Jul | I1: Aug | J1: Sep | K1: Oct | L1: Nov | M1: Dec | N1: TOTAL
A2: MONTH | B2: 1 | C2: 2 | D2: 3 | E2: 4 | F2: 5 | G2: 6 | H2: 7 | I2: 8 | J2: 9 | K2: 10 | L2: 11 | M2: 12
A3: Opening Balance | B3: ='[1]Cashflow Summary'!$O$68 -> 22229.31 | C3: =B41 -> 34922.72 | D3: =C41 -> 62971.52 | E3: =D41 -> 48601.32 | F3: =E41 -> 50245.912 | G3: =F41 -> 47890.503 | H3: =G41 -> 1357815.1 | I3: =H41 -> 1357780.1 | J3: =I41 -> 1357745.1 | ... M3: =L41 -> 1357290.1
A4: Investment - Vivek | B4: =600000-70000-25000+200000 -> 705000 | N4: =SUM(B4:M4) -> 705000
A5: Invetsment from Sharath | B5: =195000-70000 -> 125000 | N5: =SUM(B5:M5) -> 125000
N6: =SUM(B6:M6) -> 0
A7: Loan from Ramakanth | B7: 150000 | C7: -50000 | N7: =SUM(B7:M7) -> 100000
A8: Bank | B8: =2760000*70% -> 1932000
A9: Private Loan- Vijay | N9: =SUM(B9:M9) -> 0
A10: Deposit Early Release | C10: =1765000*10% -> 176500
A11: Sale 96 | D11: =1765000-C10 -> 1588500 | G11: 1800000
N12: =SUM(B12:M12) -> 0
A13: Total Income | B13: =SUM(B4:B12) -> 2912000 | C13: =SUM(C4:C12) -> 126500 | D13: =SUM(D4:D12) -> 1588500 | E13: =SUM(E4:E12) -> 0 | F13: =SUM(F4:F12) -> 0 | G13: =SUM(G4:G12) -> 1800000 | H13: =SUM(H4:H12) -> 0 | I13: =SUM(I4:I12) -> 0 | ... N13: =SUM(N4:N12) -> 930000
A14: Loan repaymnet | D14: =D11-D38+D7-10000 -> 1478500 | G14: =F44 -> 453500 | N14: =SUM(B14:M14) -> 1932000
A15: Loan Interest | B15: =$B$8*6.18%/12 -> 9949.8 | C15: =$B$8*6.18%/12 -> 9949.8 | D15: =$B$8*6.18%/12 -> 9949.8
A16: Purchase cost | B16: 2660000 | N16: =SUM(B16:M16) -> 2660000
A17: Stamp Duty+adjutsments | B17: =159400+5743.09 -> 165143.09 | N17: =SUM(B17:M17) -> 165143.09 | Q17: =150000*15%/12 -> 1875
A18: Closing cost conveyencer & adjustment | B18: =4780 -> 4780 | D18: 2500 | G18: 3500 | N18: =SUM(B18:M18) -> 10780
A19: Title Office & PEXA | B19: =3736.7+200 -> 3936.7
A20: Funding Cost | B20: =+B8*0.6% -> 11592 | N20: =SUM(B20:M20) -> 11592
A21: Audrey | B21: 11500 | N21: =SUM(B21:M21) -> 11500
A22: Demo | B22: 6600 | C22: =33000-B22 -> 26400 | N22: =SUM(C22:M22) -> 26400
A23: Homesly - Reiumbursement | B23: 13000 | N23: =SUM(B23:M23) -> 13000
A24: Water & Drainage | C24: 25000 | N24: =SUM(C24:M24) -> 25000
A25: Tree permit | B25: =350+800 -> 1150
A26: Gas Abolisgment | B26: =242*10 -> 2420 | N26: =SUM(B26:M26) -> 2420
A27: Electricty Aboloshment | B27: 3000
A28: Sewer PIC` | B28: 250
A29: PIC fire hydrand capping | B29: 750
A30: Interest Payments | C30: =(B44*6.14%)/12 -> 9885.4 | D30: =(C44*6.14%)/12 -> 9885.4 | E30: =(D44*6.14%)/12 -> 2320.4083 | F30: =(E44*6.14%)/12 -> 2320.4083 | G30: =(F44*6.14%)/12 -> 2320.4083 | H30: =(G44*6.14%)/12 -> 0 | I30: =(H44*6.14%)/12 -> 0 | J30: =(I44*6.14%)/12 -> 0 | ... M30: =(L44*6.14%)/12 -> 0 | N30: =SUM(B30:M30) -> 26732.025
A31: Council Rates | G31: 3000 | N31: =SUM(C31:M31) -> 3000
A32: Insurance | B32: 5200 | E32: -4000
A33: MISC | D33: 2000 | N33: =SUM(C33:M33) -> 2000
A34: Sales commission | C34: =1765000*1.54% -> 27181 | D34: =D10*1.54% -> 0 | E34: =E10*1.54% -> 0 | F34: =F10*1.54% -> 0 | G34: =G11*1.54% -> 27720 | N34: =SUM(B34:M34) -> 54901
A35: Land Tax | B35: 0 | N35: =SUM(B35:M35) -> 0
A36: ASIC | L36: 350 | N36: =SUM(M36:M36) -> 0
A37: Xero Fee | B37: 35 | C37: 35 | D37: 35 | E37: 35 | F37: 35 | G37: 35 | H37: 35 | I37: 35 | J37: 35 | K37: 35 | L37: 35 | M37: 35 | N37: =SUM(B37:M37) -> 420
A38: Profit distribution | D38: 100000
A39: Total Expenses | B39: =SUM(B14:B38) -> 2899306.6 | C39: =SUM(C14:C38) -> 98451.2 | D39: =SUM(D14:D38) -> 1602870.2 | E39: =SUM(E14:E38) -> -1644.5917 | F39: =SUM(F14:F38) -> 2355.4083 | G39: =SUM(G14:G38) -> 490075.41 | H39: =SUM(H14:H38) -> 35 | I39: =SUM(I14:I38) -> 35 | ... N39: =SUM(N14:N38) -> 4944888.1
A40: Net Cash flow | B40: =+B13-B39 -> 12693.41 | C40: =+C13-C39 -> 28048.8 | D40: =+D13-D39 -> -14370.2 | E40: =+E13-E39 -> 1644.5917 | F40: =+F13-F39 -> -2355.4083 | G40: =+G13-G39 -> 1309924.6 | H40: =+H13-H39 -> -35 | I40: =+I13-I39 -> -35 | ... M40: =+M13-M39 -> -35 | N40: =SUM(B40:M40) -> 1335025.8
...

Sheet 2 x Land Sales@ 70LVR
A1: Feasibility | F1: Money Partners | G1: Loan# | H1: Amt | I1: Month Loaned | J1: No. of Month | K1: Interest rate | L1: Interest | M1: Total Amt
A2: Size of each unit | B2: Sqs | C2: 0 | F2: Sharath | G2: 1 | H2: 70000 | I2: 45717 | J2: 15 | K2: 0.15 | L2: =(J2/12)*(H2*K2) -> 13125 | AA2: Settlement
A3: Total Build area in Sqm | B3: Sqm | C3: =+C2*9.29*C5 -> 0 | G3: 2 | H3: =200000-H2 -> 130000 | I3: 45992 | J3: 5 | K3: 0.15 | L3: =(J3/12)*(H3*K3) -> 8125 | M3: =SUM(L2:L3) -> 21250 | AA3: May
A4: Land area in sqm | C4: 1295 | G4: Total | H4: =SUM(H2:H3) -> 200000
A5: No of Dwellings | C5: 2 | E5: Sell per Sq M
A6: Avg Dwellings sell price | B6: 2430 | C6: =+(1765000+1775000)/2 -> 1770000 | E6: =C8/C4 -> 2733.5907 | F6: Vivek | G6: 1 | H6: 70000 | I6: 45748 | J6: 15 | K6: 0.15 | L6: =(J6/12)*(H6*K6) -> 13125
G7: 2 | H7: 100000 | I7: 46023 | J7: 5 | K7: 0.15 | L7: =(J7/12)*(H7*K7) -> 6250
A8: Total Sales | C8: =C6*C5+C7 -> 3540000 | G8: 3 | H8: =600000-H7-H6 -> 430000 | I8: 46023 | J8: 5 | K8: 0.15 | L8: =(J8/12)*(H8*K8) -> 26875 | M8: =SUM(L6:L8) -> 46250
A9: GST on margin scheme | F9: Vijay
A10: Total Revenue | B10: =C10/C10 -> 1 | C10: =+C8+C9 -> 3540000 | G10: Total | H10: =SUM(H6:H8) -> 600000
A11: All costs are GST exclusive | E11: Cost per Sqm | F11: Total Capital | H11: =+H4+H10 -> 800000
A12: Purchase price | B12: =+C12/C10 -> 0.77966102 | C12: 2760000 | E12: =+C12/C4 -> 2131.2741
A13: Stamp duty + buy in Fees | B13: 0.06 | C13: =(C12+C11)*B13 -> 165600 | F13: Ramakanth | G13: 1 | H13: 150000 | I13: 46023 | J13: 5 | K13: 0.15 | L13: =(J13/12)*(H13*K13) -> 9375 | M13: =+L13 -> 9375
A14: Finders Fee | C14: 40000 | F14: Investor 5 | G14: 1 | H14: 250000 | I14: 46023 | J14: 5 | K14: 0.15 | L14: =(J14/12)*(H14*K14) -> 15625 | M14: =+L14 -> 15625
A15: Accounting & Legals | C15: 13000
A16: Funding cost establishment cost | C16: ='Senior Funding Model'!D20 -> 22252
A17: Acquisition cost | B17: =C17/C10 -> 0.84769831 | C17: =SUM(C11:C16) -> 3000852 | F17: Capital amt | H17: =+H11+H13+H14 -> 1200000 | K17: Total Interest | L17: =SUM(L2:L16) -> 92500
A18: Due Dilligence | B18: 0.33 | C18: 0 | F18: Shortfall | H18: =F27-H17 -> -35896
A19: Utilities | B19: 0.01 | C19: 25000 | F19: Senior Debt | G19: 1 | H19: =E27 -> 1932000 | I19: 46023 | J19: 3 | K19: 0.0614 | L19: =(J19/12)*(H19*K19) -> 29656.2
B20: 0.008
A21: Marketing & selling cost | B21: 0.0154 | C21: =$C$10*B21 -> 54516 | F21: Total | H21: =H19+H17 -> 3132000 | J21: Total Funding Cost | L21: =+L19+L17 -> 122156.2
A22: Holding Cost | C22: 5000
A23: Demo | C23: =+(30000*1.1)+10000 -> 43000
A24: Misc cost | F24: Net Cashflow
A25: Total Development Cost | B25: =C25/C10 -> 0.036021469 | C25: =SUM(C18:C24) -> 127516 | R25: Burn Rate | T25: Amt | U25: Rate | V25: Per month
A26: Total Project Cost before funding | C26: =C17+C25 -> 3128368 | E26: Loan | F26: Cash required | R26: Senior Debt | T26: =H19 -> 1932000 | U26: =K19 -> 0.0614 | V26: =T26*U26/12 -> 9885.4
A27: Profit Before Funding cost | B27: =+C27/C26 -> 0.13158043 | C27: =+C10-C26 -> 411632 | E27: =C12*70% -> 1932000 | F27: =+C17-E27+C19+C23+C22+C16 -> 1164104 | R27: Private | T27: 1000000 | U27: 0.15 | V27: =U27*T27/12 -> 12500
A28: Funding Cost w/ money partners | B28: =+C28/C8 -> 0.034507401 | C28: =L21 -> 122156.2 | T28: Total | V28: =SUM(V26:V27) -> 22385.4
A29: JV Partners cost | B29: =+C29/C8 -> 0.0624718 | C29: =+B92-B87 -> 221150.17 | T29: Per block per month | V29: =V28/2 -> 11192.7
A31: Profit After Money Partners Funding | B31: =+C31/C26 -> 0.092532528 | C31: =C27-C28 -> 289475.8
A32: Profit After JV partners | B32: =C32/C26 -> 0.056661118 | C32: =B95 -> 177256.83
A33: Funding
A34: Private | B34: 800000 | C34: =+((B34*12%)/12)*5 -> 40000
A35: Mortgage | B35: 10000 | C35: 50000
C36: =SUM(C34:C35) -> 90000
A39: Cash required | C39: Amt
A40: Equity | B40: 0.3 | C40: =+C12*B40 -> 828000
A41: Stamp Duty | C41: =C13 -> 165600
A42: Demo | C42: =C23 -> 43000
A43: Funding Costs | C43: =C16 -> 22252
...

Sheet Budget vs actual
A1: Feasibility- submited to Vijay | D1: 46111
A2: Size of each unit | B2: Sqs | C2: Budget | D2: Actual | E2: Variance
A3: Total Build area in Sqm | B3: Sqm | C3: =+C2*9.29*C5 -> #VALUE!
A4: Land area in sqm | C4: 1295
A5: No of Dwellings | C5: 2
A6: Block 1 | C6: 1765000 | D6: 1765000
A7: Block 2 | C7: 1775000 | D7: 1725000
A8: Total Sales | C8: =+C7+C6 -> 3540000 | D8: =+D7+D6 -> 3490000
A9: GST on margin scheme
A10: Total Revenue | B10: =C10/C10 -> 1 | C10: =+C8+C9 -> 3540000 | D10: =+D8 -> 3490000 | E10: =+D10-C10 -> -50000
A11: All costs are GST exclusive | E11: =+D11-C11 -> 0
A12: Purchase price | B12: =+C12/C10 -> 0.77966102 | C12: 2760000 | D12: =C12 -> 2760000 | E12: =+D12-C12 -> 0
A13: Stamp duty + buy in Fees | B13: 0.06 | C13: =(C12+C11)*B13 -> 165600 | D13: =159400+3897.63 -> 163297.63 | E13: =+D13-C13 -> -2302.37
A14: Finders Fee | C14: 40000 | D14: 40000 | E14: =+D14-C14 -> 0
A15: Accounting & Legals | C15: 15000 | D15: =1850+5329.36 -> 7179.36 | E15: =+D15-C15 -> -7820.64
A16: Funding cost establishment cost | C16: ='Senior Funding Model'!D20 -> 22252 | D16: =7728+11726 -> 19454 | E16: =+D16-C16 -> -2798
A17: Acquisition cost | B17: =C17/C10 -> 0.84826328 | C17: =SUM(C11:C16) -> 3002852 | D17: =SUM(D12:D16) -> 2989931 | E17: =+D17-C17 -> -12921.01
A18: Due Dilligence | B18: 0.33 | C18: 0 | D18: 7088 | E18: =+D18-C18 -> 7088
A19: Utilities | B19: 0.01 | C19: 30000 | D19: =729.8+1259.5 -> 1989.3 | E19: =+D19-C19 -> -28010.7
A20: Arbourist | B20: 0.008 | C20: 0 | D20: 1540 | E20: =+D20-C20 -> 1540
A21: Marketing & selling cost | B21: 0.0154 | C21: 67260 | D21: 873 | E21: =+D21-C21 -> -66387
A22: Holding Cost | C22: 10000 | D22: =5904.14+43.65+145.01+935+841.46+5180 -> 13049.26 | E22: =+D22-C22 -> 3049.26
A23: Accounting | D23: =4400+124.68 -> 4524.68 | E23: =+D23-C23 -> 4524.68
A24: Council | D24: 276.71 | E24: =+D24-C24 -> 276.71
A25: Bank Fees | D25: 35 | E25: =+D25-C25 -> 35
A26: Demo | C26: 80000 | D26: 40000 | E26: =+D26-C26 -> -40000
A27: Misc cost | C27: 10000 | E27: =+D27-C27 -> -10000
A28: Total Development Cost | B28: =C28/C10 -> 0.055723164 | C28: =SUM(C18:C27) -> 197260 | D28: =SUM(D18:D27) -> 69375.95 | E28: =+D28-C28 -> -127884.05
A29: Total Project Cost before funding | C29: =C17+C28 -> 3200112 | D29: =D17+D28 -> 3059306.9 | E29: =+D29-C29 -> -140805.06
A30: Profit Before Funding cost | B30: =+C30/C29 -> 0.10621128 | C30: =+C10-C29 -> 339888 | D30: =+D10-D29 -> 430693.06 | E30: =+D30-C30 -> 90805.06
A31: Interest | B31: =+C31/C8 -> 0.012711864 | C31: 45000 | D31: 55000 | E31: =+D31-C31 -> 10000
A34: Profit after funding | C34: =C30-C31 -> 294888 | D34: =+D30-D31 -> 375693.06 | E34: =+D34-C34 -> 80805.06
C35: =+C34/C29 -> 0.092149275 | D35: =+D34/D29 -> 0.12280332 | E35: =E34/D29 -> 0.026412865

Sheet 1 land + 1 build
A1: Feasibility
A2: Size of each unit | B2: Sqs | C2: 42
A3: Total Build area in Sqm | B3: Sqm | C3: =C2*9.29 -> 390.18
A4: Land area in sqm | C4: 1295 | D4: =C12/C4 -> 2131.2741
A5: No of Dwellings | C5: 1 | D5: Sell per Sq M
A6: Land Sale | C6: 1765000 | D6: =C8/C4 -> 4065.6371
A7: House Sale | C7: 3500000
A8: Total Sales | C8: =C7+C6 -> 5265000
A9: GST on margin scheme | C9: =-(C7-(C12/2))*10% -> -212000
A10: Total Revenue | B10: =C10/C10 -> 1 | C10: =+C8+C9 -> 5053000
A11: All costs are GST exclusive
A12: Purchase price | B12: =+C12/C10 -> 0.54621017 | C12: 2760000
A13: Stamp duty + buy in Fees | B13: 0.06 | C13: =C12*B13 -> 165600
A14: Buyers fee | C14: 40000
A15: Accounting & Legals & Closing | C15: 15000
A16: Funding cost | C16: 30000
A17: Acquisition cost | B17: =C17/C10 -> 0.59580447 | C17: =SUM(C12:C16) -> 3010600 | D17: Build per sqm | E17: incd gst | F17: per dwelling
A18: Construction cost | B18: 0.25 | C18: =+B18*C10 -> 1263250 | D18: =C18/C3 -> 3237.6083 | E18: =D18*1.1 -> 3561.3691 | F18: =C18/C5 -> 1263250
A19: Townplannig | B19: 0.006 | C19: =$C$10*B19 -> 30318
A20: Buidling Permit Approvals | B20: 0.006 | C20: =$C$10*B20 -> 30318
A21: Holding Cost | B21: 0.005 | C21: =$C$10*B21 -> 25265
A22: Demo | C22: 80000
A23: Misc cost/contingency | B23: 0.01 | C23: =$C$10*B23 -> 50530
A24: Utilities | C24: 25000
A25: Total Development Cost | B25: =C25/C10 -> 0.29777973 | C25: =SUM(C18:C24) -> 1504681
A26: Total Project Cost before funding | C26: =C17+C25 -> 4515281
A27: Marketing & selling cost | B27: 0.0175 | C27: =B27*C8 -> 92137.5
A28: Profit Before Funding cost | B28: =+C28/C26 -> 0.098683006 | C28: =+C10-C26-C27 -> 445581.5
A29: Debt servicing expense | B29: 0 | C29: =$C$10*B29 -> 0
A33: Residual Value after selling 1 lot | B33: ='2 x Land Sales@ 70LVR'!B82 -> 1775000
A34: Senior loan payable | B34: =-'2 x Land Sales@ 70LVR'!B86+('1 land + 1 build'!C19+'1 land + 1 build'!C20+'1 land + 1 build'!C24) -> 429894
A35: Equity in land | B35: =B33-B34 -> 1345106
A36: Equity % | B36: =B35/B33 -> 0.7578062
A37: 80% LVR of land | B37: =B33*80% -> 1420000
A38: Interest | B38: =B37*6.5%*60%*1.5 -> 83070

Sheet 2 x single build
A1: Feasibility
A2: Size of each unit | B2: Sqs | C2: 42
A3: Total Build area in Sqm | B3: Sqm | C3: =+C2*9.29*C5 -> 780.36
A4: Land area in sqm | C4: 1295 | D4: =C12/C4 -> 2131.2741
A5: No of Dwellings | C5: 2 | D5: Sell per Sq M
A6: Avg Dwellings sell price | C6: 3500000 | D6: =C8/C4 -> 5405.4054
A8: Total Sales | C8: =C6*C5+C7 -> 7000000
A9: GST on margin scheme | C9: =-(C8-C12)*10% -> -424000
A10: Total Revenue | B10: =C10/C10 -> 1 | C10: =+C8+C9 -> 6576000
A11: All costs are GST exclusive | D11: Cost per Sqm
A12: Purchase price | B12: =+C12/C10 -> 0.41970803 | C12: 2760000 | D12: =+C12/C4 -> 2131.2741
A13: Stamp duty | B13: 0.06 | C13: =C12*B13 -> 165600
A14: Finders Fee | C14: 40000
A15: Accounting & Legals | C15: 15000
A16: initial Funding cost | C16: 25000
A17: Acquisition cost | B17: =C17/C10 -> 0.45705596 | C17: =SUM(C12:C16) -> 3005600 | D17: Build per sqm | E17: incd gst | F17: per dwelling
A18: Construction cost with pools | B18: 0.37 | C18: =+B18*C10 -> 2433120 | D18: =C18/C3 -> 3117.9456 | E18: =D18*1.1 -> 3429.7401 | F18: =C18/C5 -> 1216560
A19: Town planning approval | B19: 0.006 | C19: =$C$10*B19 -> 39456
A20: Buidling Permit Approvals | B20: 0.007 | C20: =$C$10*B20 -> 46032
A21: Holding Cost | B21: 0.01 | C21: 50000
A22: Demo | C22: 80000
A23: Misc cost | B23: 0.007 | C23: =$C$10*B23 -> 46032
A24: Utilities | C24: 25000
A25: Total Development Cost | B25: =C25/C10 -> 0.41357056 | C25: =SUM(C18:C24) -> 2719640
A26: Total Project Cost before funding | C26: =C17+C25 -> 5725240
A27: Marketing & selling cost | B27: 0.0185 | C27: =$C$10*B27 -> 121656
A28: Profit Before Funding cost | B28: =+C28/C26 -> 0.12734907 | C28: =+C10-C26-C27 -> 729104
A29: Debt servicing expense | C29: =C39 -> 342496
A34: Loan interest for land until contruction refinance | C34: 40000
A35: Refinance available 80% Of Net GRV | C35: =C10*80% -> 5260800
A36: Lending Fees | B36: 0.02 | C36: =B36*C35 -> 105216
A37: Interest | B37: 0.075 | C37: =C35*B37*50% -> 197280
A39: Total debt financeing cost | C39: =C34+C36+C37 -> 342496

Sheet Sell 1 hold 1 at 70% LVR
A1: Feasibility
A2: Size of each unit | B2: Sqs | C2: 0 | F2: Money Partners | AA2: Settlement
A3: Total Build area in Sqm | B3: Sqm | C3: =+C2*9.29*C5 -> 0 | G3: Loan# | H3: Amt | I3: Month Loaned | J3: No. of Month | K3: Interest rate | L3: Interest | M3: Total Amt | AA3: May
A4: Land area in sqm | C4: 1295 | F4: Sharath | G4: 1 | H4: 70000 | I4: 45717 | J4: 15 | K4: 0.15 | L4: =(J4/12)*(H4*K4) -> 13125
A5: No of Dwellings | C5: 1 | E5: Sell per Sq M | G5: 2 | H5: =200000-H4 -> 130000 | I5: 45992 | J5: 5 | K5: 0.15 | L5: =(J5/12)*(H5*K5) -> 8125 | M5: =SUM(L4:L5) -> 21250
A6: Avg Dwellings sell price | B6: 2430 | C6: =1760000 -> 1760000 | E6: =C8/C4 -> 1359.0734 | G6: Total | H6: =SUM(H4:H5) -> 200000
A8: Total Sales | C8: =C6*C5+C7 -> 1760000 | F8: Vivek | G8: 1 | H8: 70000 | I8: 45748 | J8: 15 | K8: 0.15 | L8: =(J8/12)*(H8*K8) -> 13125
A9: GST on margin scheme | G9: 2 | H9: 100000 | I9: 46023 | J9: 5 | K9: 0.15 | L9: =(J9/12)*(H9*K9) -> 6250
A10: Total Revenue | B10: =C10/C10 -> 1 | C10: =+C8+C9 -> 1760000 | G10: 3 | H10: =400000-H9-H8 -> 230000 | I10: 46023 | J10: 5 | K10: 0.15 | L10: =(J10/12)*(H10*K10) -> 14375 | M10: =SUM(L8:L10) -> 33750
A11: All costs are GST exclusive | E11: Cost per Sqm | G11: Total | H11: =SUM(H8:H10) -> 400000
A12: Purchase price | C12: 2760000 | E12: =+C12/C4 -> 2131.2741 | F12: Total Capital | H12: =+H6+H11 -> 600000
A13: Stamp duty + buy in Fees | B13: 0.06 | C13: =(C12+C11)*B13 -> 165600
A14: Finders Fee | C14: 40000 | F14: Ramakanth | G14: 1 | H14: 150000 | I14: 46023 | J14: 5 | K14: 0.15 | L14: =(J14/12)*(H14*K14) -> 9375 | M14: =+L14 -> 9375
A15: Accounting & Legals | C15: 15000 | F15: Investor 4 | G15: 1 | H15: 250000 | I15: 46023 | J15: 5 | K15: 0.15 | L15: =(J15/12)*(H15*K15) -> 15625 | M15: =+L15 -> 15625
A16: Funding Fee | C16: ='Senior Funding Model'!D20 -> 22252
A17: Acquisition cost | B17: =C17/C10 -> 1.7061659 | C17: =SUM(C11:C16) -> 3002852
A18: Water Tappings | F18: Capital amt | H18: =+H12+H14+H15 -> 1000000 | K18: Total Interest | L18: =SUM(L4:L17) -> 80000
A19: Utilities | B19: 0.01 | C19: 25000
B20: 0.008 | F20: Senior Debt | G20: 1 | H20: =#REF! -> #REF! | I20: 46023 | J20: 5 | K20: 0.08 | L20: =(J20/12)*(H20*K20) -> #REF!
A21: Marketing & selling cost | B21: 0.0165 | C21: =$C$10*B21 -> 29040
A22: Holding Cost | C22: 5000 | F22: Total | H22: =H20+H18 -> #REF! | J22: Total Funding Cost | L22: =+L20+L18 -> #REF!
A23: Demo | C23: 70000 | F23: Net Cashflow
A24: Misc cost
A25: Funding cost establishment cost
A26: Total Development Cost | B26: =C26/C10 -> 0.073318182 | C26: =SUM(C18:C25) -> 129040 | E26: Loan | F26: Cash required | R26: Burn Rate | T26: Amt | U26: Rate | V26: Per month
E27: =C12*70% -> 1932000 | F27: =C17+C19+C22+C23-E27 -> 1170852 | R27: Senior Debt | T27: =H20 -> #REF! | U27: =K20 -> 0.08 | V27: =T27*U27/12 -> #REF!
A31: Minus Net sales from 1 block | C31: =C10 -> 1760000
A32: Minus sales commission | C32: =-C21 -> -29040
A33: pay off loan amount | C33: -1709468
C35: =SUM(C30:C34) -> 21492
A37: Initial loan amount | C37: =+E27 -> 1932000
A38: Minus Principle paid off | C38: =-C33 -> 1709468
A39: Balance of loan | C39: =+C37-C38 -> 222532
A41: Initial cash required | C41: =+F27 -> 1170852
A42: JV partners contribution | C42: ='Capital Stack'!B25 -> 1145000
A43: Money partners contribution | C43: =+C41-C42 -> 25852
C45: Y 1 | D45: Yr 2 | E45: Yr 3
A46: If sell the secon block | C46: 1850000 | D46: 1900000 | E46: 2000000
A47: Loan | C47: =$C$39 -> 222532 | D47: =$C$39 -> 222532 | E47: =$C$39 -> 222532
A48: JV Partners | C48: =$C42 -> 1145000 | D48: =$C42 -> 1145000 | E48: =$C42 -> 1145000
...

Sheet 7 Yr Valuation & Cashflow JV
A1: Yr # | C1: 1 | D1: 2 | E1: 3 | F1: 4 | G1: 5 | H1: 6 | I1: 7
A2: Financial Yr | C2: 2026 | D2: 2027 | E2: 2028 | F2: 2029 | G2: 2030 | H2: 2031 | I2: 2032
A3: Capital Growth | D3: =(D5-C5)/C5 -> 0.23188406 | E3: 0.05 | F3: 0.05 | G3: 0.05 | H3: 0.05 | I3: 0.05
A4: Valuation per block | C4: =+C5/2 -> 1380000 | D4: =+D5/2 -> 1700000 | E4: =+E5/2 -> 1785000 | F4: =+F5/2 -> 1874250 | G4: =+G5/2 -> 1967962.5 | H4: =+H5/2 -> 2066360.6 | I4: =+I5/2 -> 2169678.7
A5: Property Valuation | C5: 2760000 | D5: =1700000*2 -> 3400000 | E5: =+D5*(100%+E3) -> 3570000 | F5: =+E5*(100%+F3) -> 3748500 | G5: =+F5*(100%+G3) -> 3935925 | H5: =+G5*(100%+H3) -> 4132721.2 | I5: =+H5*(100%+I3) -> 4339357.3
A6: Increase In Value | D6: =+D5-C5 -> 640000 | E6: =+E5-D5 -> 170000 | F6: =+F5-E5 -> 178500 | G6: =+G5-F5 -> 187425 | H6: =+H5-G5 -> 196796.25 | I6: =+I5-H5 -> 206636.06 | K6: 800000
A7: StampDuty | C7: =C5*6% -> 165600 | J7: The is a land with 2 titles
A8: Closing cost + Due Diligence | C8: 8000 | J8: Can I nominate it as main residence to get CGT excemption - intention is to renovate a unit and move in - But we may consider to re-develop the land or sell it within 7 years.
A9: Finders fee | C9: 30000 | J9: Can I borrow money from a friends SMSF as a personal loan towards Equity for the purchase. If that’s not possible, Homelsy Pty can borrow but how to I get that across towards Equity towards Purchase
A10: Operating Reserve & Repairs | C10: 60000
A11: Total Cost | C11: =SUM(C5:C10) -> 3023600
A13: Loan @ 70% LVR | C13: =C5*70% -> 1932000 | D13: =D5*70% -> 2380000 | E13: =E5*70% -> 2499000 | F13: =F5*70% -> 2623950 | G13: =G5*70% -> 2755147.5 | H13: =H5*70% -> 2892904.9 | I13: =I5*70% -> 3037550.1
A14: Equity required @ 30% purchase | C14: =+C5*30% -> 828000 | D14: =+D5*30% -> 1020000 | E14: =+E5*30% -> 1071000 | F14: =+F5*30% -> 1124550 | G14: =+G5*30% -> 1180777.5 | H14: =+H5*30% -> 1239816.4 | I14: =+I5*30% -> 1301807.2
A15: Private Funds Required incd costs | C15: =C11-C13 -> 1091600
A16: JV at 80% Equity | B16: =+C16/C15 -> 0.91608648 | C16: 1000000 | D16: 1000000 | E16: 1000000 | F16: 1000000 | G16: 1000000 | H16: 800000 | I16: 800000
A17: Dev Equity | B17: =C17/C15 -> 0.083913521 | C17: =C15-C16 -> 91600 | D17: =C17 -> 91600 | E17: =D17 -> 91600 | F17: =E17 -> 91600 | G17: =F17 -> 91600 | H17: =G17 -> 91600 | I17: =H17 -> 91600
A18: Dev Private Iinterest | B18: 0.12 | C18: =(C17*12%)/2 -> 5496 | D18: =(D17*12%) -> 10992 | E18: =(E17*12%) -> 10992 | F18: =(F17*12%) -> 10992 | G18: =(G17*12%) -> 10992 | H18: =(H17*12%) -> 10992 | I18: =(I17*12%) -> 10992
A20: If sold Profit | C20: =D5-C5-C7-C8-C9-C10-C18 -> 370904 | D20: =E5-C11+C48-D18-C18 -> 512722.4 | E20: =F5-C11+C48+D48-C18-D18-E18 -> 676394.4 | F20: =G5-C11+C48+D48+E48-C18-D18-E18-F18 -> 858919 | G20: =H5-C11+C48+D48+E48+F48+G48-C18-D18-E18-F18-G18 -> 1128503.5
A21: Profit Increase | D21: =D20/C20-100% -> 0.38235878 | E21: =E20/D20-100% -> 0.31922147 | F21: =F20/E20-100% -> 0.26984937 | G21: =G20/F20-100% -> 0.31386481
A22: JV Proft Split | B22: 0.7 | C22: =C20*$B$22 -> 259632.8 | D22: =D20*$B$22 -> 358905.68 | E22: =E20*$B$22 -> 473476.08 | F22: =F20*$B$22 -> 601243.3 | G22: =G20*$B$22 -> 789952.42
A23: dev Return % | C23: =+C22/C16*2 -> 0.5192656 | D23: =(D22/D16)/1.5 -> 0.23927045 | E23: =(E22/E16)/2.5 -> 0.18939043 | F23: =(F22/F16)/3.5 -> 0.1717838 | G23: =(G22/G16)/4.5 -> 0.17554498
A25: Dev Profit Split | B25: =100%-B22 -> 0.3 | C25: =$B$25*C20 -> 111271.2 | D25: =$B$25*D20 -> 153816.72 | E25: =$B$25*E20 -> 202918.32 | F25: =$B$25*F20 -> 257675.7 | G25: =$B$25*G20 -> 338551.04
A26: Dev Profit -minus Private Interest | C26: =C25-C18 -> 105775.2 | D26: =D25-D18-C18 -> 137328.72 | E26: =E25-E18-D18-C18 -> 175438.32 | F26: =F25-F18-E18-D18-C18 -> 219203.7 | G26: =G25-G18-F18-E18-D18-C18 -> 289087.04
A29: Cashflow
A30: Rental Growth | D30: 0.05 | E30: =+E31/D31 -> 1.0683007 | F30: 0.04 | G30: 0.04 | H30: 0.04 | I30: 0.04
A31: Rev | C31: ='Cash Flow FY1'!B22 -> 69120 | D31: ='Cash Flow FY2'!B21 -> 183600 | E31: ='Cash Flow FY3'!B21 -> 196140 | F31: ='Cash Flow FY4'!B21 -> 206550 | G31: ='Cash Flow FY5'!B21 -> 216750 | H31: ='Cash Flow FY4'!D21 -> 16200 | I31: ='Cash Flow FY4'!E21 -> 20250
A32: Expenes
A33: Interest Payments | C33: ='Cash Flow FY1'!B3 -> 59312.4 | D33: ='Cash Flow FY2'!B2 -> 115920 | E33: ='Cash Flow FY3'!B2 -> 115920 | F33: ='Cash Flow FY4'!B2 -> 115920 | G33: =+F33*(100%+$B$33) -> 115920 | H33: =+G33*(100%+$B$33) -> 115920 | I33: =+H33*(100%+$B$33) -> 115920
A34: Council Rates | C34: ='Cash Flow FY1'!B4 -> 6350 | D34: ='Cash Flow FY2'!B3 -> 12720 | E34: ='Cash Flow FY3'!B3 -> 12780 | F34: ='Cash Flow FY4'!B3 -> 13163.4 | G34: =+F34*(100%+$B34) -> 13163.4 | H34: =+G34*(100%+$B34) -> 13163.4 | I34: =+H34*(100%+$B34) -> 13163.4
A35: Insurance | C35: ='Cash Flow FY1'!B5 -> 3000 | D35: ='Cash Flow FY2'!B4 -> 6000 | E35: ='Cash Flow FY3'!B4 -> 7800 | F35: ='Cash Flow FY4'!B4 -> 8400 | G35: =+F35*(100%+$B35) -> 8400 | H35: =+G35*(100%+$B35) -> 8400 | I35: =+H35*(100%+$B35) -> 8400
A36: Landscaping | C36: ='Cash Flow FY1'!B6 -> 1500 | D36: ='Cash Flow FY2'!B5 -> 3600 | E36: ='Cash Flow FY3'!B5 -> 3600 | F36: ='Cash Flow FY4'!B5 -> 3600 | G36: =+F36*(100%+$B36) -> 3600 | H36: =+G36*(100%+$B36) -> 3600 | I36: =+H36*(100%+$B36) -> 3600
A37: Repairs & Maintaince | C37: ='Cash Flow FY1'!B7 -> 2500 | D37: ='Cash Flow FY2'!B6 -> 6180 | E37: ='Cash Flow FY3'!B6 -> 6180 | F37: ='Cash Flow FY4'!B6 -> 6180 | G37: =+F37*(100%+$B37) -> 6180 | H37: =+G37*(100%+$B37) -> 6180 | I37: =+H37*(100%+$B37) -> 6180
A38: Property Management | C38: ='Cash Flow FY1'!B8 -> 4147.2 | D38: ='Cash Flow FY2'!B7 -> 11016 | E38: ='Cash Flow FY3'!B7 -> 11768.4 | F38: ='Cash Flow FY4'!B7 -> 12393
A39: Misc | C39: ='Cash Flow FY1'!B9 -> 5500 | D39: ='Cash Flow FY2'!B8 -> 2000 | E39: ='Cash Flow FY3'!B8 -> 2000 | F39: ='Cash Flow FY4'!B8 -> 2000 | G39: ='Cash Flow FY4'!C8 -> 0 | H39: ='Cash Flow FY4'!D8 -> 0 | I39: ='Cash Flow FY4'!E8 -> 1000
A40: Land Tax | C40: ='Cash Flow FY1'!B10 -> 0 | D40: 30000 | E40: 30000 | F40: 30000
A41: Letting Fee | C41: ='Cash Flow FY1'!B11 -> 2000 | D41: ='Cash Flow FY2'!B10 -> 0 | E41: ='Cash Flow FY3'!B10 -> 0 | F41: ='Cash Flow FY4'!B10 -> 0 | G41: 600 | H41: 600 | I41: 600
A42: Advertising | C42: ='Cash Flow FY1'!B12 -> 2000 | D42: ='Cash Flow FY2'!B11 -> 0 | E42: ='Cash Flow FY3'!B11 -> 0 | F42: ='Cash Flow FY4'!B11 -> 0 | G42: =+F42*(100%+$B42) -> 0 | H42: =+G42*(100%+$B42) -> 0 | I42: =+H42*(100%+$B42) -> 0
A47: Total Expense | C47: =SUM(C33:C43) -> 86309.6 | D47: =SUM(D33:D43) -> 187436 | E47: =SUM(E33:E43) -> 190048.4 | F47: =SUM(F33:F43) -> 191656.4 | G47: =SUM(G33:G43) -> 147863.4 | H47: =SUM(H33:H43) -> 147863.4 | I47: =SUM(I33:I43) -> 148863.4
A48: Net Cashflow | C48: =C31-C47 -> -17189.6 | D48: =D31-D47 -> -3836 | E48: =E31-E47 -> 6091.6 | F48: =F31-F47 -> 14893.6 | G48: =G31-G47 -> 68886.6 | H48: =H31-H47 -> -131663.4 | I48: =I31-I47 -> -128613.4
A49: Net operating Profit | C49: =C48+C33 -> 42122.8 | D49: =D48+D33 -> 112084 | E49: =E48+E33 -> 122011.6 | F49: =F48+F33 -> 130813.6 | G49: =G48+G33 -> 184806.6 | H49: =H48+H33 -> -15743.4 | I49: =I48+I33 -> -12693.4
...

Sheet Senior Funding Model
A1: As of 28th October | B1: Think Tank 70% | C1: Think Tank 80% | D1: Westpac 70%
A2: Loan Amount | B2: =70%*2760000 -> 1932000 | C2: =80%*2760000 -> 2208000 | D2: =2760000*70% -> 1932000 | F2: Inputs | J2: Servicability Requirements
A3: Equity Required | B3: =3150000-B2 -> 1218000 | C3: =3150000-C2 -> 942000 | D3: =3150000-D2 -> 1218000 | F3: Purchase price | G3: ='7 Yr Valuation & Cashflow'!C5 -> 2760000 | K3: Loan Amt | L3: Interest | M3: Net Income Req | N3: Fixed Expense | O3: Flexible Exp | P3: Net Rent | Q3: Sinead IncomeNet | R3: Sub Total | S3: Net KR Salary | T3: KR Gross Saalry
A4: Costs | F4: Interest rate assessed | G4: 0.075 | J4: =F6 -> LVR 80% | K4: =G3*G6 -> 2208000 | L4: =K4*(G$4+G$5) -> 231840 | M4: =L4*G$9 -> 347760 | N4: -54000 | O4: 0 | P4: =H24 -> 128250 | Q4: 66228 | R4: =SUM(N4:Q4) -> 140478 | S4: =M4-R4 -> 207282 | T4: 350000
A5: Broker Fee | B5: 0 | C5: 0 | D5: 0.0055 | F5: Buffer | G5: 0.03 | J5: =F7 -> LVR 70% | K5: =G3*G7 -> 1932000 | L5: =K5*(G$4+G$5) -> 202860 | M5: =L5*G$9 -> 304290 | N5: -54000 | O5: 0 | P5: =G$24 -> 120042 | Q5: 66228 | R5: =SUM(N5:Q5) -> 132270 | S5: =M5-R5 -> 172020 | T5: 265000
A6: Establishment Fee | B6: 0.00475 | C6: 0.00475 | D6: 0.006 | F6: LVR 80% | G6: 0.8 | J6: =F8 -> LVR 65% | K6: =G3*G8 -> 1794000 | L6: =K6*(G$4+G$5) -> 188370 | M6: =L6*G$9 -> 282555 | N6: -54000 | O6: 0 | P6: =G$24 -> 120042 | Q6: 66228 | R6: =SUM(N6:Q6) -> 132270 | S6: =M6-R6 -> 150285 | T6: 225000
A7: Legals | B7: 0.001 | C7: 0.001 | D7: 0 | F7: LVR 70% | G7: 0.7
A8: Settlement Fee | B8: 495 | C8: 495 | D8: 1000 | F8: LVR 65% | G8: 0.65
A9: Deffered Fee (months Interest) | B9: 0.083333333 | C9: 0.083333333 | D9: 0 | F9: Servicability Ratio to Income | G9: 1.5
A10: Interest Rate | B10: 0.0769 | C10: 0.0817 | D10: 0.0614 | F10: Income Considered from Rent | G10: 0.9
A11: Interest per year | B11: =+B10*B2 -> 148570.8 | C11: =+C10*C2 -> 180393.6 | D11: =+D10*D2 -> 118624.8 | F11: Vacancy Rate | G11: 0.05
A12: Fee | F12: Monthly Household Expenses w/ 1 dependant | G12: 4500
A13: Broker Fee | B13: =+B5*B2 -> 0 | C13: =+C5*C2 -> 0 | D13: =0.005*D2 -> 9660
A14: Establishment Fee | B14: =+B6*B2 -> 9177 | C14: =+C6*C2 -> 10488 | D14: =+D6*D2 -> 11592
A15: Legals | B15: =+B7*B2 -> 1932 | C15: =+C7*C2 -> 2208 | D15: =+D7*D2 -> 0 | F15: Annual Expenses
A16: Settlement Fee | B16: =B8 -> 495 | C16: =C8 -> 495 | D16: =D8 -> 1000 | F16: Monthly Expenses | G16: =+G12*12 -> 54000
A17: Deffered Fee (months Interest) | B17: =B2*B10*B9 -> 12380.9 | C17: =C2*C10*C9 -> 15032.8 | D17: =D2*D10*D9 -> 0 | F17: Flexible Expense
F18: 657A Nepean Hwy Loan | G18: =6900*12 -> 82800
F19: Total Expenses | G19: =SUM(G16:G18) -> 136800
A20: Total Fees | B20: =SUM(B13:B19) -> 23984.9 | C20: =SUM(C13:C19) -> 28223.8 | D20: =SUM(D13:D19) -> 22252
F21: Rent | G21: 270 | H21: 290
F22: Rental Income | G22: 140400 | H22: 150000
F23: Net rental income (after 5% vacancy) | G23: =G22*(100%-G11) -> 133380 | H23: =+H22*(100%-G11) -> 142500
F24: Rental shading 90% | G24: =G23*G10 -> 120042 | H24: =H23*G10 -> 128250

Sheet 7 Yr Valuation & Cashflow
A1: Yr # | C1: 1 | D1: 2 | E1: 3 | F1: 4 | G1: 5 | H1: 6 | I1: 7
A2: Financial Yr | C2: 2026 | D2: 2027 | E2: 2028 | F2: 2029 | G2: 2030 | H2: 2031 | I2: 2032
A3: Capital Growth | D3: =(D5-C5)/C5 -> 0.37681159 | E3: 0.05 | F3: 0.05 | G3: 0.05 | H3: 0.05 | I3: 0.05
A4: Valuation per block | C4: =+C5/2 -> 1380000 | D4: =+D5/2 -> 1900000 | E4: =+E5/2 -> 1995000 | F4: =+F5/2 -> 2094750 | G4: =+G5/2 -> 2199487.5 | H4: =+H5/2 -> 2309461.9 | I4: =+I5/2 -> 2424935 | K4: Cash required | L4: Capital stack
A5: Property Valuation | C5: 2760000 | D5: =1900000*2 -> 3800000 | E5: =+D5*(100%+E3) -> 3990000 | F5: =+E5*(100%+F3) -> 4189500 | G5: =+F5*(100%+G3) -> 4398975 | H5: =+G5*(100%+H3) -> 4618923.8 | I5: =+H5*(100%+I3) -> 4849869.9 | K5: Equity | L5: =C5*30% -> 828000
A6: Increase In Value | D6: =+D5-C5 -> 1040000 | E6: =+E5-D5 -> 190000 | F6: =+F5-E5 -> 199500 | G6: =+G5-F5 -> 209475 | H6: =+H5-G5 -> 219948.75 | I6: =+I5-H5 -> 230946.19 | K6: Working Capital | L6: ='Capital Stack'!B9-'7 Yr Valuation & Cashflow'!L5-'Capital Stack'!B13 -> 371892
A7: StampDuty | C7: =C5*6% -> 165600
A8: Closing cost + Due Diligence | C8: 15000 | K8: Total Cash Required | L8: =SUM(L5:L7) -> 1199892
A9: Finders fee | C9: 40000 | K9: Loan | L9: =+'Capital Stack'!B13 -> 1932000
A10: Operating Reserve & Repairs | C10: =150000+30000 -> 180000 | K10: Capital Stack | L10: =SUM(L8:L9) -> 3131892
A11: Finance Cost | C11: ='Senior Funding Model'!D20 -> 22252
A12: Total Cost | C12: =SUM(C5:C11) -> 3182852 | L12: Amt | M12: Share
K13: Capital Raised - Round 1 | L13: 800000 | M13: =+(L13/850000)*0.45 -> 0.42352941
A14: Loan @ 70% LVR | C14: =C5*70% -> 1932000 | D14: =C14 -> 1932000 | E14: =E5*70% -> 2793000 | F14: =F5*70% -> 2932650 | G14: =G5*70% -> 3079282.5 | H14: =H5*70% -> 3233246.6 | I14: =I5*70% -> 3394909 | K14: Deficit - Round 2 | L14: =+L8-L13 -> 399892 | M14: 0.18
A15: Equity / cash Required | C15: =L8 -> 1199892 | D15: =C15 -> 1199892 | E15: =D15 -> 1199892 | F15: =E15 -> 1199892 | G15: =F15 -> 1199892 | H15: =+H5*30% -> 1385677.1 | I15: =+I5*30% -> 1454961 | K15: Total Investors | L15: =SUM(L13:L14) -> 1199892 | M15: =SUM(M13:M14) -> 0.60352941
A16: Refinance Surplus | C16: 0 | D16: =+D14-C14 -> 0 | E16: =+E14-D14 -> 861000 | F16: =+F14-E14 -> 139650 | G16: =+G14-F14 -> 146632.5 | H16: =+H14-G14 -> 153964.12 | I16: =+I14-H14 -> 161662.33 | K16: Developer | L16: 0 | M16: =100%-M15 -> 0.39647059
H17: =H5*20%-#REF! -> #REF! | I17: =I5*20%-#REF! -> #REF!
A18: Exit Model | H18: =+H5-G14-#REF!-#REF!-5000 -> #REF! | I18: =+I5-H14-#REF!-#REF!-5000 -> #REF!
A19: Sales commission-1.65% | D19: =1.65%*D5+10000 -> 72700 | E19: =1.65%*E5+10000 -> 75835 | F19: =1.65%*F5+10000 -> 79126.75 | G19: =1.65%*G5+10000 -> 82583.088 | H19: =H5-$C$5 -> 1858923.8 | I19: =I5-$C$5 -> 2089869.9
A20: Closing Costs | C20: =C18*$B$20 -> 0 | D20: 5000 | E20: 5001 | F20: 5002 | G20: 5003 | H20: =H18-((H19/2)*32%) -> #REF! | I20: =I18-((I19/2)*32%) -> #REF! | L20: Think Tank
A21: Cost of selling | C21: =C18*$B$21 -> 0 | D21: =+D19+D20 -> 77700 | E21: =+E19+E20 -> 80836 | F21: =+F19+F20 -> 84128.75 | G21: =+G19+G20 -> 87586.088 | H21: 800000 | I21: 800000 | K21: Feasibility | L21: Refinancing | M21: Sale
A22: Profit $ | D22: =D5-$C$12-D21 -> 539448 | E22: =E5-$C$12-E21 -> 726312 | F22: =F5-$C$12-F21 -> 922519.25 | G22: =G5-$C$12-G21 -> 1128536.9 | H22: =G22 -> 1128536.9 | I22: =H22 -> 1128536.9 | L22: Amt | M22: Amt
A23: Profit % | D23: =D22/$C$12 -> 0.16948573 | E23: =E22/$C$12 -> 0.22819534 | F23: =F22/$C$12 -> 0.28984045 | G23: =G22/$C$12 -> 0.35456783 | K23: Sale of Property | L23: 3800000 | M23: 3800000
H24: =+H22/2 -> 564268.46 | I24: =+I22/2 -> 564268.46 | K24: Net Rental cashflow incd outgoings | L24: -5000 | M24: -5000
A25: Developer Profit | B25: =M16 -> 0.39647059 | D25: =+D22*$B25 -> 213875.27 | E25: =+E22*$B25 -> 287961.35 | F25: =+F22*$B25 -> 365751.75 | G25: =+G22*$B25 -> 447431.69 | H25: =+H22*35% -> 394987.92 | I25: =+I22*35% -> 394987.92 | K25: Total Revenue | L25: =SUM(L23:L24) -> 3795000 | M25: =SUM(M23:M24) -> 3795000
A26: Investor Profit | B26: =M15 -> 0.60352941 | D26: =D22*$B$26 -> 325572.73 | E26: =E22*$B$26 -> 438350.65 | F26: =F22*$B$26 -> 556767.5 | G26: =G22*$B$26 -> 681105.22 | K26: Purchase Price | L26: 2760000 | M26: 2760000
A27: Investors returns % per Yr | D27: =(D26/$L$15)/(D1-1) -> 0.27133503 | E27: =(E26/$L$15)/(E1-1) -> 0.18266255 | F27: =(F26/$L$15)/(F1-1) -> 0.15467156 | G27: =(G26/$L$15)/(G1-1) -> 0.14190969 | K27: StampDuty | L27: =L26*6% -> 165600 | M27: =M26*6% -> 165600
A28: Total Investor Retunr | D28: =D26/$L$15 -> 0.27133503 | E28: =E26/$L$15 -> 0.36532509 | F28: =F26/$L$15 -> 0.46401468 | G28: =G26/$L$15 -> 0.56763877 | K28: Closing cost + Due Diligence | L28: 15000 | M28: 15000
A29: Rental Growth | D29: 0.05 | E29: =(E30/D30)-100% -> 0.068300654 | F29: =(F30/E30)-100% -> 0.053074335 | G29: =(G30/F30)-100% -> 0.049382716 | H29: =(H30/G30)-100% -> -0.92525952 | I29: =(I30/H30)-100% -> 0.25 | K29: Finders fee | L29: 40000 | M29: 40000
A30: Rev | C30: ='Cash Flow FY1'!B22 -> 69120 | D30: ='Cash Flow FY2'!B21 -> 183600 | E30: ='Cash Flow FY3'!B21 -> 196140 | F30: ='Cash Flow FY4'!B21 -> 206550 | G30: ='Cash Flow FY5'!B21 -> 216750 | H30: ='Cash Flow FY4'!D21 -> 16200 | I30: ='Cash Flow FY4'!E21 -> 20250 | K30: Operating Reserve & Repairs | L30: 150000 | M30: 150000
A31: Expenes | K31: Finance Cost (settlement) | L31: 20000 | M31: 20000
A32: Interest Payments | C32: ='Cash Flow FY1'!B3 -> 59312.4 | D32: ='Cash Flow FY2'!B2 -> 115920 | E32: ='Cash Flow FY3'!B2 -> 115920 | F32: ='Cash Flow FY4'!B2 -> 115920 | G32: ='Cash Flow FY5'!B2 -> 115920 | H32: =+G32*(100%+$B$32) -> 115920 | I32: =+H32*(100%+$B$32) -> 115920 | K32: Refinancing cost | L32: 30000
A33: Outgoings | K33: Sales commission & Marketing cost | M33: =+M23*1.5% + 10000 -> 67000
A34: Council Rates | C34: ='Cash Flow FY1'!B4 -> 6350 | D34: ='Cash Flow FY2'!B3 -> 12720 | E34: ='Cash Flow FY3'!B3 -> 12780 | F34: ='Cash Flow FY4'!B3 -> 13163.4 | G34: ='Cash Flow FY5'!B3 -> 15600 | H34: =+G34*(100%+$B34) -> 15600 | I34: =+H34*(100%+$B34) -> 15600 | K34: Total Cost | L34: =SUM(L26:L33) -> 3180600 | M34: =SUM(M26:M33) -> 3217600
A35: Insurance | C35: ='Cash Flow FY1'!B5 -> 3000 | D35: ='Cash Flow FY2'!B4 -> 6000 | E35: ='Cash Flow FY3'!B4 -> 7800 | F35: ='Cash Flow FY4'!B4 -> 8400 | G35: ='Cash Flow FY5'!B4 -> 8400 | H35: =+G35*(100%+$B35) -> 8400 | I35: =+H35*(100%+$B35) -> 8400
A36: Landscaping | C36: ='Cash Flow FY1'!B6 -> 1500 | D36: ='Cash Flow FY2'!B5 -> 3600 | E36: ='Cash Flow FY3'!B5 -> 3600 | F36: ='Cash Flow FY4'!B5 -> 3600 | G36: ='Cash Flow FY5'!B5 -> 3600 | H36: =+G36*(100%+$B36) -> 3600 | I36: =+H36*(100%+$B36) -> 3600 | K36: Profit $ | L36: =L25-L34 -> 614400 | M36: =M25-M34 -> 577400
A37: Repairs & Maintaince | C37: ='Cash Flow FY1'!B7 -> 2500 | D37: ='Cash Flow FY2'!B6 -> 6180 | E37: ='Cash Flow FY3'!B6 -> 6180 | F37: ='Cash Flow FY4'!B6 -> 6180 | G37: ='Cash Flow FY5'!B6 -> 6180 | H37: =+G37*(100%+$B37) -> 6180 | I37: =+H37*(100%+$B37) -> 6180 | K37: Profit on cost | L37: =+L36/L34 -> 0.1931711 | M37: =+M36/M34 -> 0.17945052
A38: Property Management | C38: ='Cash Flow FY1'!B8 -> 4147.2 | D38: ='Cash Flow FY2'!B7 -> 11016 | E38: ='Cash Flow FY3'!B7 -> 11768.4 | F38: ='Cash Flow FY4'!B7 -> 12393 | G38: ='Cash Flow FY5'!B7 -> 13005 | H38: ='Cash Flow FY4'!D7 -> 972 | I38: ='Cash Flow FY4'!E7 -> 1215
A39: Misc | C39: ='Cash Flow FY1'!B9 -> 5500 | D39: ='Cash Flow FY2'!B8 -> 2000 | E39: ='Cash Flow FY3'!B8 -> 2000 | F39: ='Cash Flow FY4'!B8 -> 2000 | G39: ='Cash Flow FY5'!B8 -> 2000 | H39: ='Cash Flow FY4'!D8 -> 0 | I39: ='Cash Flow FY4'!E8 -> 1000
A40: Land Tax | C40: ='Cash Flow FY1'!B10 -> 0 | D40: ='Cash Flow FY2'!$B9 -> 29000 | E40: ='Cash Flow FY2'!$B9 -> 29000 | F40: ='Cash Flow FY2'!$B9 -> 29000 | G40: ='Cash Flow FY2'!$B9 -> 29000
...

Sheet Cash Flow FY1
A1: Expenses | C1: 46023 | D1: 46054 | E1: 46082 | F1: 46113 | G1: 46143 | H1: 46174
A2: Total | B2: =SUM(B3:B16) -> 86309.6 | C2: =SUM(C3:C16) -> 16616.533 | D2: =SUM(D3:D16) -> 14262.133 | E2: =SUM(E3:E16) -> 14607.733 | F2: =SUM(F3:F16) -> 14607.733 | G2: =SUM(G3:G16) -> 13107.733 | H2: =SUM(H3:H16) -> 13107.733
A3: Interest Payments | B3: =SUM(C3:H3) -> 59312.4 | C3: =+((2760000*70%)*6.14%)/12 -> 9885.4 | D3: =+((2760000*70%)*6.14%)/12 -> 9885.4 | E3: =+((2760000*70%)*6.14%)/12 -> 9885.4 | F3: =+((2760000*70%)*6.14%)/12 -> 9885.4 | G3: =+((2760000*70%)*6.14%)/12 -> 9885.4 | H3: =+((2760000*70%)*6.14%)/12 -> 9885.4
A4: Council Rates | B4: =SUM(C4:H4) -> 6350 | C4: =+(1270*10)/12 -> 1058.3333 | D4: =+(1270*10)/12 -> 1058.3333 | E4: =+(1270*10)/12 -> 1058.3333 | F4: =+(1270*10)/12 -> 1058.3333 | G4: =+(1270*10)/12 -> 1058.3333 | H4: =+(1270*10)/12 -> 1058.3333
A5: Insurance | B5: =SUM(C5:H5) -> 3000 | C5: 500 | D5: 500 | E5: 500 | F5: 500 | G5: 500 | H5: 500
A6: Landscaping | B6: =SUM(C6:H6) -> 1500 | D6: 300 | E6: 300 | F6: 300 | G6: 300 | H6: 300
A7: Repairs & Maintaince | B7: =SUM(C7:H7) -> 2500 | D7: 500 | E7: 500 | F7: 500 | G7: 500 | H7: 500
A8: Property Management 6% | B8: =SUM(C8:H8) -> 4147.2 | C8: =+C22*6% -> 172.8 | D8: =+D22*6% -> 518.4 | E8: =+E22*6% -> 864 | F8: =+F22*6% -> 864 | G8: =+G22*6% -> 864 | H8: =+H22*6% -> 864
A9: Leasing Fee 3% | B9: =SUM(C9:H9) -> 5500 | C9: 2200 | D9: 1100 | E9: 1100 | F9: 1100
A10: Land Tax | B10: =SUM(C10:H10) -> 0
A11: Letting Fee | B11: =SUM(C11:H11) -> 2000 | C11: =200*C20 -> 800 | D11: =200*(D20-C20) -> 400 | E11: =200*(E20-D20) -> 400 | F11: =200*(F20-E20) -> 400 | G11: =200*(G20-F20) -> 0 | H11: =200*(H20-G20) -> 0
A12: Advertising | B12: =SUM(C12:H12) -> 2000 | C12: 2000
B14: =SUM(C14:H14) -> 0
B15: =SUM(C15:H15) -> 0
B16: =SUM(C16:H16) -> 0
A18: Income
A19: Rent Per Unit | C19: 360 | D19: 360 | E19: 360 | F19: 360 | G19: 360 | H19: 360
A20: No. of Units Rented | C20: 4 | D20: 6 | E20: 8 | F20: 10 | G20: 10 | H20: 10
A21: No. Of weeks | B21: =SUM(C21:H21) -> 23 | C21: 2 | D21: 4 | E21: 5 | F21: 4 | G21: 4 | H21: 4
A22: Total Income | B22: =SUM(C22:H22) -> 69120 | C22: =+C19*C20*C21 -> 2880 | D22: =+D19*D20*D21 -> 8640 | E22: =+E19*E20*E21 -> 14400 | F22: =+F19*F20*F21 -> 14400 | G22: =+G19*G20*G21 -> 14400 | H22: =+H19*H20*H21 -> 14400
B23: =SUM(C23:H23) -> 0
B24: =SUM(C24:H24) -> 0
A25: Net Cash flow | B25: =B22-B2 -> -17189.6 | C25: =C22-C2 -> -13736.533 | D25: =D22-D2 -> -5622.1333 | E25: =E22-E2 -> -207.73333 | F25: =F22-F2 -> -207.73333 | G25: =G22-G2 -> 1292.2667 | H25: =H22-H2 -> 1292.2667

Sheet Cash Flow FY2
A1: Expenses | B1: Totals | C1: 46204 | D1: 46235 | E1: 46266 | F1: 46296 | G1: 46327 | H1: 46357 | I1: 46388 | J1: 46419 | K1: 46447 | L1: 46478 | M1: 46508 | N1: 46539
A2: Interest Payments | B2: =SUM(C2:N2) -> 115920 | C2: =+((2760000*70%)*6%)/12 -> 9660 | D2: =+((2760000*70%)*6%)/12 -> 9660 | E2: =+((2760000*70%)*6%)/12 -> 9660 | F2: =+((2760000*70%)*6%)/12 -> 9660 | G2: =+((2760000*70%)*6%)/12 -> 9660 | H2: =+((2760000*70%)*6%)/12 -> 9660 | I2: =+((2760000*70%)*6%)/12 -> 9660 | J2: =+((2760000*70%)*6%)/12 -> 9660 | ... N2: =+((2760000*70%)*6%)/12 -> 9660
A3: Council Rates | B3: =SUM(C3:N3) -> 12720 | C3: 1060 | D3: 1060 | E3: 1060 | F3: 1060 | G3: 1060 | H3: 1060 | I3: 1060 | J3: 1060 | K3: 1060 | L3: 1060 | M3: 1060 | N3: 1060
A4: Insurance | B4: =SUM(C4:N4) -> 6000 | C4: 500 | D4: 500 | E4: 500 | F4: 500 | G4: 500 | H4: 500 | I4: 500 | J4: 500 | K4: 500 | L4: 500 | M4: 500 | N4: 500
A5: Landscaping | B5: =SUM(C5:N5) -> 3600 | C5: 300 | D5: 300 | E5: 300 | F5: 300 | G5: 300 | H5: 300 | I5: 300 | J5: 300 | K5: 300 | L5: 300 | M5: 300 | N5: 300
A6: Repairs & Maintaince | B6: =SUM(C6:N6) -> 6180 | C6: =500*1.03 -> 515 | D6: =500*1.03 -> 515 | E6: =500*1.03 -> 515 | F6: =500*1.03 -> 515 | G6: =500*1.03 -> 515 | H6: =500*1.03 -> 515 | I6: =500*1.03 -> 515 | J6: =500*1.03 -> 515 | ... N6: =500*1.03 -> 515
A7: Property Management 6% | B7: =SUM(C7:N7) -> 11016 | C7: =+C21*6% -> 1080 | D7: =+D21*6% -> 864 | E7: =+E21*6% -> 1080 | F7: =+F21*6% -> 864 | G7: =+G21*6% -> 864 | H7: =+H21*6% -> 864 | I7: =+I21*6% -> 864 | J7: =+J21*6% -> 907.2 | ... N7: =+N21*6% -> 907.2
A8: Misc | B8: =SUM(C8:N8) -> 2000 | E8: 1000 | K8: 1000
A9: Land Tax | B9: =SUM(C9:N9) -> 29000 | M9: 29000
A10: Letting Fee | B10: =SUM(C10:N10) -> 0 | G10: =200*(G19-F19) -> 0 | H10: =200*(H19-G19) -> 0 | J10: =200*(J19-I19) -> 0 | K10: =200*(K19-J19) -> 0 | L10: =200*(L19-K19) -> 0 | M10: =200*(M19-L19) -> 0 | N10: =200*(N19-M19) -> 0
A11: Advertising | B11: =SUM(C11:N11) -> 0
B12: =SUM(C12:N12) -> 0
B14: =SUM(C14:N14) -> 0
A15: Total Expenses | B15: =SUM(B2:B14) -> 186436 | C15: =SUM(C2:C14) -> 13115 | D15: =SUM(D2:D14) -> 12899 | E15: =SUM(E2:E14) -> 14115 | F15: =SUM(F2:F14) -> 12899 | G15: =SUM(G2:G14) -> 12899 | H15: =SUM(H2:H14) -> 12899 | I15: =SUM(I2:I14) -> 12899 | ... N15: =SUM(N2:N14) -> 12942.2
A17: Income | B17: Increase | J17: 0.05
A18: Rent Per Unit | C18: 360 | D18: 360 | E18: 360 | F18: 360 | G18: 360 | H18: 360 | I18: 360 | J18: =+I18*(100%+J17) -> 378 | K18: =+J18*(100%+K17) -> 378 | L18: =+K18*(100%+L17) -> 378 | M18: =+L18*(100%+M17) -> 378 | N18: =+M18*(100%+N17) -> 378
A19: No. of Units Rented | C19: 10 | D19: 10 | E19: 10 | F19: 10 | G19: 10 | H19: 10 | I19: 10 | J19: 10 | K19: 10 | L19: 10 | M19: 10 | N19: 10
A20: No. Of weeks | B20: =SUM(C20:N20) -> 50 | C20: 5 | D20: 4 | E20: 5 | F20: 4 | G20: 4 | H20: 4 | I20: 4 | J20: 4 | K20: 4 | L20: 4 | M20: 4 | N20: 4
A21: Total Income | B21: =SUM(C21:N21) -> 183600 | C21: =+C18*C19*C20 -> 18000 | D21: =+D18*D19*D20 -> 14400 | E21: =+E18*E19*E20 -> 18000 | F21: =+F18*F19*F20 -> 14400 | G21: =+G18*G19*G20 -> 14400 | H21: =+H18*H19*H20 -> 14400 | I21: =+I18*I19*I20 -> 14400 | J21: =+J18*J19*J20 -> 15120 | ... N21: =+N18*N19*N20 -> 15120
A23: Net Cash flow | B23: =B21-B15 -> -2836 | C23: =C21-C15 -> 4885 | D23: =D21-D15 -> 1501 | E23: =E21-E15 -> 3885 | F23: =F21-F15 -> 1501 | G23: =G21-G15 -> 1501 | H23: =H21-H15 -> 1501 | I23: =I21-I15 -> 1501 | ... N23: =N21-N15 -> 2177.8

Sheet Cash Flow FY3
A1: Expenses | B1: Totals | C1: 46569 | D1: 46600 | E1: 46631 | F1: 46661 | G1: 46692 | H1: 46722 | I1: 46753 | J1: 46784 | K1: 46813 | L1: 46844 | M1: 46874 | N1: 46905
A2: Interest Payments | B2: =SUM(C2:N2) -> 115920 | C2: =+((2760000*70%)*6%)/12 -> 9660 | D2: =+((2760000*70%)*6%)/12 -> 9660 | E2: =+((2760000*70%)*6%)/12 -> 9660 | F2: =+((2760000*70%)*6%)/12 -> 9660 | G2: =+((2760000*70%)*6%)/12 -> 9660 | H2: =+((2760000*70%)*6%)/12 -> 9660 | I2: =+((2760000*70%)*6%)/12 -> 9660 | J2: =+((2760000*70%)*6%)/12 -> 9660 | ... N2: =+((2760000*70%)*6%)/12 -> 9660
A3: Council Rates | B3: =SUM(C3:N3) -> 12780 | C3: 1065 | D3: 1065 | E3: 1065 | F3: 1065 | G3: 1065 | H3: 1065 | I3: 1065 | J3: 1065 | K3: 1065 | L3: 1065 | M3: 1065 | N3: 1065
A4: Insurance | B4: =SUM(C4:N4) -> 7800 | C4: 650 | D4: 650 | E4: 650 | F4: 650 | G4: 650 | H4: 650 | I4: 650 | J4: 650 | K4: 650 | L4: 650 | M4: 650 | N4: 650
A5: Landscaping | B5: =SUM(C5:N5) -> 3600 | C5: 300 | D5: 300 | E5: 300 | F5: 300 | G5: 300 | H5: 300 | I5: 300 | J5: 300 | K5: 300 | L5: 300 | M5: 300 | N5: 300
A6: Repairs & Maintaince | B6: =SUM(C6:N6) -> 6180 | C6: =500*1.03 -> 515 | D6: =500*1.03 -> 515 | E6: =500*1.03 -> 515 | F6: =500*1.03 -> 515 | G6: =500*1.03 -> 515 | H6: =500*1.03 -> 515 | I6: =500*1.03 -> 515 | J6: =500*1.03 -> 515 | ... N6: =500*1.03 -> 515
A7: Property Management | B7: =SUM(C7:N7) -> 11768.4 | C7: =+C21*6% -> 1134 | D7: =+D21*6% -> 907.2 | E7: =+E21*6% -> 1158 | F7: =+F21*6% -> 926.4 | G7: =+G21*6% -> 926.4 | H7: =+H21*6% -> 926.4 | I7: =+I21*6% -> 926.4 | J7: =+J21*6% -> 972.72 | ... N7: =+N21*6% -> 972.72
A8: Misc | B8: =SUM(C8:N8) -> 2000 | E8: 1000 | K8: 1000
A9: Land Tax | B9: =SUM(C9:N9) -> 29000 | M9: 29000
A10: Letting Fee | B10: =SUM(C10:N10) -> 0
A11: Advertising | B11: =SUM(C11:N11) -> 0
B12: =SUM(C12:N12) -> 0
B14: =SUM(C14:N14) -> 0
A15: Total | B15: =SUM(B2:B14) -> 189048.4 | C15: =SUM(C2:C14) -> 13324 | D15: =SUM(D2:D14) -> 13097.2 | E15: =SUM(E2:E14) -> 14348 | F15: =SUM(F2:F14) -> 13116.4 | G15: =SUM(G2:G14) -> 13116.4 | H15: =SUM(H2:H14) -> 13116.4 | I15: =SUM(I2:I14) -> 13116.4 | ... N15: =SUM(N2:N14) -> 13162.72
B16: =SUM(C16:N16) -> 0
A17: Income | B17: =SUM(C17:N17) -> 0.05 | J17: 0.05
A18: Rent Per Unit | C18: ='Cash Flow FY2'!N18 -> 378 | D18: 378 | E18: 386 | F18: 386 | G18: 386 | H18: 386 | I18: 386 | J18: =+I18*(100%+J17) -> 405.3 | K18: =+J18*(100%+K17) -> 405.3 | L18: =+K18*(100%+L17) -> 405.3 | M18: =+L18*(100%+M17) -> 405.3 | N18: =+M18*(100%+N17) -> 405.3
A19: No. of Units Rented | C19: 10 | D19: 10 | E19: 10 | F19: 10 | G19: 10 | H19: 10 | I19: 10 | J19: 10 | K19: 10 | L19: 10 | M19: 10 | N19: 10
A20: No. Of weeks | B20: =SUM(C20:N20) -> 50 | C20: 5 | D20: 4 | E20: 5 | F20: 4 | G20: 4 | H20: 4 | I20: 4 | J20: 4 | K20: 4 | L20: 4 | M20: 4 | N20: 4
A21: Total Income | B21: =SUM(C21:N21) -> 196140 | C21: =+C18*C19*C20 -> 18900 | D21: =+D18*D19*D20 -> 15120 | E21: =+E18*E19*E20 -> 19300 | F21: =+F18*F19*F20 -> 15440 | G21: =+G18*G19*G20 -> 15440 | H21: =+H18*H19*H20 -> 15440 | I21: =+I18*I19*I20 -> 15440 | J21: =+J18*J19*J20 -> 16212 | ... N21: =+N18*N19*N20 -> 16212
B22: =SUM(C22:N22) -> 0
B23: =SUM(C23:N23) -> 0
A24: Net Cash flow | B24: =B21-B15 -> 7091.6 | C24: =C21-C15 -> 5576 | D24: =D21-D15 -> 2022.8 | E24: =E21-E15 -> 4952 | F24: =F21-F15 -> 2323.6 | G24: =G21-G15 -> 2323.6 | H24: =H21-H15 -> 2323.6 | I24: =I21-I15 -> 2323.6 | ... N24: =N21-N15 -> 3049.28

Sheet Cash Flow FY4
A1: Expenses | B1: Totals | C1: 46569 | D1: 46600 | E1: 46631 | F1: 46661 | G1: 46692 | H1: 46722 | I1: 46753 | J1: 46784 | K1: 46813 | L1: 46844 | M1: 46874 | N1: 46905
A2: Interest Payments | B2: =SUM(C2:N2) -> 115920 | C2: =+((2760000*70%)*6%)/12 -> 9660 | D2: =+((2760000*70%)*6%)/12 -> 9660 | E2: =+((2760000*70%)*6%)/12 -> 9660 | F2: =+((2760000*70%)*6%)/12 -> 9660 | G2: =+((2760000*70%)*6%)/12 -> 9660 | H2: =+((2760000*70%)*6%)/12 -> 9660 | I2: =+((2760000*70%)*6%)/12 -> 9660 | J2: =+((2760000*70%)*6%)/12 -> 9660 | ... N2: =+((2760000*70%)*6%)/12 -> 9660
A3: Council Rates | B3: =SUM(C3:N3) -> 13163.4 | C3: =1065*1.03 -> 1096.95 | D3: =1065*1.03 -> 1096.95 | E3: =1065*1.03 -> 1096.95 | F3: =1065*1.03 -> 1096.95 | G3: =1065*1.03 -> 1096.95 | H3: =1065*1.03 -> 1096.95 | I3: =1065*1.03 -> 1096.95 | J3: =1065*1.03 -> 1096.95 | ... N3: =1065*1.03 -> 1096.95
A4: Insurance | B4: =SUM(C4:N4) -> 8400 | C4: 700 | D4: 700 | E4: 700 | F4: 700 | G4: 700 | H4: 700 | I4: 700 | J4: 700 | K4: 700 | L4: 700 | M4: 700 | N4: 700
A5: Landscaping | B5: =SUM(C5:N5) -> 3600 | C5: 300 | D5: 300 | E5: 300 | F5: 300 | G5: 300 | H5: 300 | I5: 300 | J5: 300 | K5: 300 | L5: 300 | M5: 300 | N5: 300
A6: Repairs & Maintaince | B6: =SUM(C6:N6) -> 6180 | C6: =500*1.03 -> 515 | D6: =500*1.03 -> 515 | E6: =500*1.03 -> 515 | F6: =500*1.03 -> 515 | G6: =500*1.03 -> 515 | H6: =500*1.03 -> 515 | I6: =500*1.03 -> 515 | J6: =500*1.03 -> 515 | ... N6: =500*1.03 -> 515
A7: Property Management | B7: =SUM(C7:N7) -> 12393 | C7: =+C21*6% -> 1215 | D7: =+D21*6% -> 972 | E7: =+E21*6% -> 1215 | F7: =+F21*6% -> 972 | G7: =+G21*6% -> 972 | H7: =+H21*6% -> 972 | I7: =+I21*6% -> 972 | J7: =+J21*6% -> 1020.6 | ... N7: =+N21*6% -> 1020.6
A8: Misc | B8: =SUM(C8:N8) -> 2000 | E8: 1000 | K8: 1000
A9: Land Tax | B9: =SUM(C9:N9) -> 29000 | M9: 29000
A10: Letting Fee | B10: =SUM(C10:N10) -> 0
A11: Advertising | B11: =SUM(C11:N11) -> 0
B12: =SUM(C12:N12) -> 0
B14: =SUM(C14:N14) -> 0
A15: Total | B15: =SUM(B2:B14) -> 190656.4 | C15: =SUM(C2:C14) -> 13486.95 | D15: =SUM(D2:D14) -> 13243.95 | E15: =SUM(E2:E14) -> 14486.95 | F15: =SUM(F2:F14) -> 13243.95 | G15: =SUM(G2:G14) -> 13243.95 | H15: =SUM(H2:H14) -> 13243.95 | I15: =SUM(I2:I14) -> 13243.95 | ... N15: =SUM(N2:N14) -> 13292.55
B16: =SUM(C16:N16) -> 0
A17: Income | B17: =SUM(C17:N17) -> 0.05 | J17: 0.05
A18: Rent Per Unit | C18: 405 | D18: 405 | E18: 405 | F18: 405 | G18: 405 | H18: 405 | I18: 405 | J18: =+I18*(100%+J17) -> 425.25 | K18: =+J18*(100%+K17) -> 425.25 | L18: =+K18*(100%+L17) -> 425.25 | M18: =+L18*(100%+M17) -> 425.25 | N18: =+M18*(100%+N17) -> 425.25
A19: No. of Units Rented | C19: 10 | D19: 10 | E19: 10 | F19: 10 | G19: 10 | H19: 10 | I19: 10 | J19: 10 | K19: 10 | L19: 10 | M19: 10 | N19: 10
A20: No. Of weeks | B20: =SUM(C20:N20) -> 50 | C20: 5 | D20: 4 | E20: 5 | F20: 4 | G20: 4 | H20: 4 | I20: 4 | J20: 4 | K20: 4 | L20: 4 | M20: 4 | N20: 4
A21: Total Income | B21: =SUM(C21:N21) -> 206550 | C21: =+C18*C19*C20 -> 20250 | D21: =+D18*D19*D20 -> 16200 | E21: =+E18*E19*E20 -> 20250 | F21: =+F18*F19*F20 -> 16200 | G21: =+G18*G19*G20 -> 16200 | H21: =+H18*H19*H20 -> 16200 | I21: =+I18*I19*I20 -> 16200 | J21: =+J18*J19*J20 -> 17010 | ... N21: =+N18*N19*N20 -> 17010
B22: =SUM(C22:N22) -> 0
B23: =SUM(C23:N23) -> 0
A24: Net Cash flow | B24: =B21-B15 -> 15893.6 | C24: =C21-C15 -> 6763.05 | D24: =D21-D15 -> 2956.05 | E24: =E21-E15 -> 5763.05 | F24: =F21-F15 -> 2956.05 | G24: =G21-G15 -> 2956.05 | H24: =H21-H15 -> 2956.05 | I24: =I21-I15 -> 2956.05 | ... N24: =N21-N15 -> 3717.45

Sheet Cash Flow FY5
A1: Expenses | B1: Totals | C1: 46569 | D1: 46600 | E1: 46631 | F1: 46661 | G1: 46692 | H1: 46722 | I1: 46753 | J1: 46784 | K1: 46813 | L1: 46844 | M1: 46874 | N1: 46905
A2: Interest Payments | B2: =SUM(C2:N2) -> 115920 | C2: =+((2760000*70%)*6%)/12 -> 9660 | D2: =+((2760000*70%)*6%)/12 -> 9660 | E2: =+((2760000*70%)*6%)/12 -> 9660 | F2: =+((2760000*70%)*6%)/12 -> 9660 | G2: =+((2760000*70%)*6%)/12 -> 9660 | H2: =+((2760000*70%)*6%)/12 -> 9660 | I2: =+((2760000*70%)*6%)/12 -> 9660 | J2: =+((2760000*70%)*6%)/12 -> 9660 | ... N2: =+((2760000*70%)*6%)/12 -> 9660
A3: Council Rates | B3: =SUM(C3:N3) -> 15600 | C3: 1300 | D3: 1300 | E3: 1300 | F3: 1300 | G3: 1300 | H3: 1300 | I3: 1300 | J3: 1300 | K3: 1300 | L3: 1300 | M3: 1300 | N3: 1300
A4: Insurance | B4: =SUM(C4:N4) -> 8400 | C4: 700 | D4: 700 | E4: 700 | F4: 700 | G4: 700 | H4: 700 | I4: 700 | J4: 700 | K4: 700 | L4: 700 | M4: 700 | N4: 700
A5: Landscaping | B5: =SUM(C5:N5) -> 3600 | C5: 300 | D5: 300 | E5: 300 | F5: 300 | G5: 300 | H5: 300 | I5: 300 | J5: 300 | K5: 300 | L5: 300 | M5: 300 | N5: 300
A6: Repairs & Maintaince | B6: =SUM(C6:N6) -> 6180 | C6: =500*1.03 -> 515 | D6: =500*1.03 -> 515 | E6: =500*1.03 -> 515 | F6: =500*1.03 -> 515 | G6: =500*1.03 -> 515 | H6: =500*1.03 -> 515 | I6: =500*1.03 -> 515 | J6: =500*1.03 -> 515 | ... N6: =500*1.03 -> 515
A7: Property Management | B7: =SUM(C7:N7) -> 13005 | C7: =+C21*6% -> 1275 | D7: =+D21*6% -> 1020 | E7: =+E21*6% -> 1275 | F7: =+F21*6% -> 1020 | G7: =+G21*6% -> 1020 | H7: =+H21*6% -> 1020 | I7: =+I21*6% -> 1020 | J7: =+J21*6% -> 1071 | ... N7: =+N21*6% -> 1071
A8: Misc | B8: =SUM(C8:N8) -> 2000 | E8: 1000 | K8: 1000
A9: Land Tax | B9: =SUM(C9:N9) -> 29000 | M9: 29000
A10: Letting Fee | B10: =SUM(C10:N10) -> 0
A11: Advertising | B11: =SUM(C11:N11) -> 0
B12: =SUM(C12:N12) -> 0
B14: =SUM(C14:N14) -> 0
A15: Total | B15: =SUM(B2:B14) -> 193705 | C15: =SUM(C2:C14) -> 13750 | D15: =SUM(D2:D14) -> 13495 | E15: =SUM(E2:E14) -> 14750 | F15: =SUM(F2:F14) -> 13495 | G15: =SUM(G2:G14) -> 13495 | H15: =SUM(H2:H14) -> 13495 | I15: =SUM(I2:I14) -> 13495 | ... N15: =SUM(N2:N14) -> 13546
B16: =SUM(C16:N16) -> 0
A17: Income | B17: =SUM(C17:N17) -> 0.05 | J17: 0.05
A18: Rent Per Unit | C18: 425 | D18: 425 | E18: 425 | F18: 425 | G18: 425 | H18: 425 | I18: 425 | J18: =+I18*(100%+J17) -> 446.25 | K18: =+J18*(100%+K17) -> 446.25 | L18: =+K18*(100%+L17) -> 446.25 | M18: =+L18*(100%+M17) -> 446.25 | N18: =+M18*(100%+N17) -> 446.25
A19: No. of Units Rented | C19: 10 | D19: 10 | E19: 10 | F19: 10 | G19: 10 | H19: 10 | I19: 10 | J19: 10 | K19: 10 | L19: 10 | M19: 10 | N19: 10
A20: No. Of weeks | B20: =SUM(C20:N20) -> 50 | C20: 5 | D20: 4 | E20: 5 | F20: 4 | G20: 4 | H20: 4 | I20: 4 | J20: 4 | K20: 4 | L20: 4 | M20: 4 | N20: 4
A21: Total Income | B21: =SUM(C21:N21) -> 216750 | C21: =+C18*C19*C20 -> 21250 | D21: =+D18*D19*D20 -> 17000 | E21: =+E18*E19*E20 -> 21250 | F21: =+F18*F19*F20 -> 17000 | G21: =+G18*G19*G20 -> 17000 | H21: =+H18*H19*H20 -> 17000 | I21: =+I18*I19*I20 -> 17000 | J21: =+J18*J19*J20 -> 17850 | ... N21: =+N18*N19*N20 -> 17850
B22: =SUM(C22:N22) -> 0
B23: =SUM(C23:N23) -> 0
A24: Net Cash flow | B24: =B21-B15 -> 23045 | C24: =C21-C15 -> 7500 | D24: =D21-D15 -> 3505 | E24: =E21-E15 -> 6500 | F24: =F21-F15 -> 3505 | G24: =G21-G15 -> 3505 | H24: =H21-H15 -> 3505 | I24: =I21-I15 -> 3505 | ... N24: =N21-N15 -> 4304

Sheet 2 x Land Sales@ 80 LVR
A1: Feasibility
A2: Size of each unit | B2: Sqs | C2: 0 | F2: Money Partners | AA2: Settlement
A3: Total Build area in Sqm | B3: Sqm | C3: =+C2*9.29*C5 -> 0 | G3: Loan# | H3: Amt | I3: Month Loaned | J3: No. of Month | K3: Interest rate | L3: Interest | M3: Total Amt | AA3: May
A4: Land area in sqm | C4: 1295 | F4: Sharath | G4: 1 | H4: 70000 | I4: 45717 | J4: 15 | K4: 0.15 | L4: =(J4/12)*(H4*K4) -> 13125
A5: No of Dwellings | C5: 2 | E5: Sell per Sq M | G5: 2 | H5: =200000-H4 -> 130000 | I5: 45992 | J5: 5 | K5: 0.15 | L5: =(J5/12)*(H5*K5) -> 8125 | M5: =SUM(L4:L5) -> 21250
A6: Avg Dwellings sell price | B6: 2430 | C6: =+(1750000+1800000)/2 -> 1775000 | E6: =C8/C4 -> 2741.3127 | G6: Total | H6: =SUM(H4:H5) -> 200000
A8: Total Sales | C8: =C6*C5+C7 -> 3550000 | F8: Vivek | G8: 1 | H8: 70000 | I8: 45748 | J8: 15 | K8: 0.15 | L8: =(J8/12)*(H8*K8) -> 13125
A9: GST on margin scheme | G9: 2 | H9: 100000 | I9: 46023 | J9: 5 | K9: 0.15 | L9: =(J9/12)*(H9*K9) -> 6250
A10: Total Revenue | B10: =C10/C10 -> 1 | C10: =+C8+C9 -> 3550000 | G10: 3 | H10: =400000-H9-H8 -> 230000 | I10: 46023 | J10: 5 | K10: 0.15 | L10: =(J10/12)*(H10*K10) -> 14375 | M10: =SUM(L8:L10) -> 33750
